I'm sorry, but an uncaught exception occurred.

While running game code:
  File "game/script.rpy", line 331, in script
    a" Их подрыв должен пробить отверстие около двух метров в диаметре: Более чем достаточно"
Exception: Sayer 'a' is not defined.

-- Full Traceback ------------------------------------------------------------

Full traceback:
  File "game/script.rpy", line 331, in script
    a" Их подрыв должен пробить отверстие около двух метров в диаметре: Более чем достаточно"
  File "D:\Programs\renpy-8.3.7-sdk\renpy\ast.py", line 2586, in execute
    Say.execute(self)
  File "D:\Programs\renpy-8.3.7-sdk\renpy\ast.py", line 583, in execute
    who = eval_who(self.who, self.who_fast)
  File "D:\Programs\renpy-8.3.7-sdk\renpy\ast.py", line 472, in eval_who
    raise Exception("Sayer '%s' is not defined." % who)
Exception: Sayer 'a' is not defined.

Windows-10-10.0.26100 AMD64
Ren'Py 8.3.7.25031702
Honor in Law 1.0
Tue Apr  1 15:59:33 2025
